<?xml version="1.0" encoding="utf-8"?>
<!-- =================================================================================== -->
<!-- |    This document was autogenerated by xacro from zzx_run_robot.urdf.xacro       | -->
<!-- |    EDITING THIS FILE BY HAND IS NOT RECOMMENDED                                 | -->
<!-- =================================================================================== -->
<!-- This xacro was created by ZZX-->
<robot name="zzx_run_robot" xmlns:controller="http://playerstage.sourceforge.net/gazebo/xmlschema/#controller" xmlns:interface="http://playerstage.sourceforge.net/gazebo/xmlschema/#interface" xmlns:sensor="http://playerstage.sourceforge.net/gazebo/xmlschema/#sensor">
  <!--base_link-->
  <link name="base_link">
    <inertial>
      <origin rpy="0 0 0" xyz="0.00741047992278929 -0.00341114189657439 0.114186284669122"/>
      <mass value="3.96236436148786"/>
      <inertia ixx="0.178506185725259" ixy="0.000108304306880873" ixz="0.000169549055394087" iyy="0.404759631587269" iyz="1.00448230235288E-06" izz="0.561130623679876"/>
    </inertial>
    <visual>
      <origin rpy="0 0 0" xyz="0 0 0"/>
      <geometry>
        <mesh filename="package://zzx_run_description/meshes/base_link.STL"/>
      </geometry>
      <material name="">
        <color rgba="0.792156862745098 0.819607843137255 0.933333333333333 1"/>
      </material>
    </visual>
    <collision>
      <origin rpy="0 0 0" xyz="0 0 0"/>
      <geometry>
        <mesh filename="package://zzx_run_description/meshes/base_link.STL"/>
      </geometry>
    </collision>
  </link>
  <!--base_footprint-->
  <link name="base_footprint">
    <visual>
      <origin rpy="0 0 0" xyz="0 0 0"/>
      <geometry>
        <box size="0.001 0.001 0.001"/>
      </geometry>
    </visual>
  </link>
  <joint name="base_footprint_joint" type="fixed">
    <origin rpy="0 0 0" xyz="0 0 0.06746"/>
    <parent link="base_footprint"/>
    <child link="base_link"/>
  </joint>
  <!--left_front_wheel_link-->
  <link name="left_front_wheel_link">
    <inertial>
      <origin rpy="0 0 0" xyz="-4.78387528979329E-07 0.0527999229567212 -1.21519264034697E-06"/>
      <mass value="5.58816289074736"/>
      <inertia ixx="0.0467264175417539" ixy="4.21922638423182E-10" ixz="4.31360254637763E-10" iyy="0.0872654610518181" iyz="5.11812738578019E-11" izz="0.0467264187453853"/>
    </inertial>
    <visual>
      <origin rpy="0 0 0" xyz="0 0 0"/>
      <geometry>
        <mesh filename="package://zzx_run_description/meshes/left_front_wheel_link.dae"/>
      </geometry>
      <material name="">
        <color rgba="0.0 0.0 0.0 1.0"/>
      </material>
    </visual>
    <collision>
      <origin rpy="0 0 0" xyz="0 0 0"/>
      <geometry>
        <mesh filename="package://zzx_run_description/meshes/left_front_wheel_link.dae"/>
      </geometry>
    </collision>
  </link>
  <!--left_front_wheel_link_joint-->
  <joint name="left_front_wheel_link_joint" type="continuous">
    <origin rpy="0 0 0" xyz="0.25 0.25 0.05"/>
    <parent link="base_link"/>
    <child link="left_front_wheel_link"/>
    <axis xyz="0 1 0"/>
  </joint>
  <!--left_behind_wheel_link-->
  <link name="left_behind_wheel_link">
    <inertial>
      <origin rpy="0 0 0" xyz="1.31378196099874E-07 0.0527999220844182 -1.30022679351027E-06"/>
      <mass value="5.58816261475792"/>
      <inertia ixx="0.0467264178495617" ixy="-1.48432408253074E-10" ixz="3.45934344448938E-11" iyy="0.0872654610290871" iyz="5.288073487882E-10" izz="0.0467264184119642"/>
    </inertial>
    <visual>
      <origin rpy="0 0 0" xyz="0 0 0"/>
      <geometry>
        <mesh filename="package://zzx_run_description/meshes/left_behind_wheel_link.dae"/>
      </geometry>
      <material name="">
        <color rgba="0.0 0.0 0.0 1.0"/>
      </material>
    </visual>
    <collision>
      <origin rpy="0 0 0" xyz="0 0 0"/>
      <geometry>
        <mesh filename="package://zzx_run_description/meshes/left_behind_wheel_link.dae"/>
      </geometry>
    </collision>
  </link>
  <!--left_behind_wheel_link_joint-->
  <joint name="left_behind_wheel_link_joint" type="continuous">
    <origin rpy="0 0 0" xyz="-0.25 0.25 0.05"/>
    <parent link="base_link"/>
    <child link="left_behind_wheel_link"/>
    <axis xyz="0 1 0"/>
  </joint>
  <!--right_front_wheel_link-->
  <link name="right_front_wheel_link">
    <inertial>
      <origin rpy="0 0 0" xyz="1.23487383696386E-06 -0.052800077037773 4.18657537137879E-07"/>
      <mass value="5.58816289283226"/>
      <inertia ixx="0.0467264183997509" ixy="-4.77846900738126E-10" ixz="9.0196657416584E-11" iyy="0.0872654610291803" iyz="-2.63885619866361E-10" izz="0.0467264178624116"/>
    </inertial>
    <visual>
      <origin rpy="0 0 0" xyz="0 0 0"/>
      <geometry>
        <mesh filename="package://zzx_run_description/meshes/right_front_wheel_link.dae"/>
      </geometry>
      <material name="">
        <color rgba="0.0 0.0 0.0 1.0"/>
      </material>
    </visual>
    <collision>
      <origin rpy="0 0 0" xyz="0 0 0"/>
      <geometry>
        <mesh filename="package://zzx_run_description/meshes/right_front_wheel_link.dae"/>
      </geometry>
    </collision>
  </link>
  <!--right_front_wheel_link_joint-->
  <joint name="right_front_wheel_link_joint" type="continuous">
    <origin rpy="0 0 0" xyz="0.25 -0.25 0.05"/>
    <parent link="base_link"/>
    <child link="right_front_wheel_link"/>
    <axis xyz="0 1 0"/>
  </joint>
  <!--right_behind_wheel_link-->
  <link name="right_behind_wheel_link">
    <inertial>
      <origin rpy="0 0 0" xyz="-1.17487549072814E-06 -0.0528000779026511 5.64813343303938E-07"/>
      <mass value="5.58816261843466"/>
      <inertia ixx="0.0467264186791865" ixy="2.30502475654598E-11" ixz="-5.12433901318596E-10" iyy="0.0872654610531356" iyz="-4.26967668323502E-10" izz="0.0467264176094793"/>
    </inertial>
    <visual>
      <origin rpy="0 0 0" xyz="0 0 0"/>
      <geometry>
        <mesh filename="package://zzx_run_description/meshes/right_behind_wheel_link.dae"/>
      </geometry>
      <material name="">
        <color rgba="0.0 0.0 0.0 1.0"/>
      </material>
    </visual>
    <collision>
      <origin rpy="0 0 0" xyz="0 0 0"/>
      <geometry>
        <mesh filename="package://zzx_run_description/meshes/right_behind_wheel_link.dae"/>
      </geometry>
    </collision>
  </link>
  <!--right_behind_wheel_link_joint-->
  <joint name="right_behind_wheel_link_joint" type="continuous">
    <origin rpy="0 0 0" xyz="-0.25 -0.25 0.05"/>
    <parent link="base_link"/>
    <child link="right_behind_wheel_link"/>
    <axis xyz="0 1 0"/>
  </joint>
  <joint name="velodyne_base_mount_joint" type="fixed">
    <origin rpy="0 0 0" xyz="0.2 0 0.5"/>
    <parent link="base_link"/>
    <child link="velodyne_base_link"/>
  </joint>
  <link name="velodyne_base_link">
    <inertial>
      <mass value="0.01"/>
      <origin xyz="0 0 0.03585"/>
      <inertia ixx="1.0940475e-05" ixy="0" ixz="0" iyy="1.0940475e-05" iyz="0" izz="1.33128e-05"/>
    </inertial>
    <visual>
      <geometry>
        <mesh filename="package://velodyne_description/meshes/VLP16_base_1.dae"/>
      </geometry>
    </visual>
    <visual>
      <geometry>
        <mesh filename="package://velodyne_description/meshes/VLP16_base_2.dae"/>
      </geometry>
    </visual>
    <collision>
      <origin rpy="0 0 0" xyz="0 0 0.03585"/>
      <geometry>
        <cylinder length="0.0717" radius="0.0516"/>
      </geometry>
    </collision>
  </link>
  <joint name="velodyne_base_scan_joint" type="fixed">
    <origin rpy="0 0 0" xyz="0 0 0.0377"/>
    <parent link="velodyne_base_link"/>
    <child link="velodyne"/>
  </joint>
  <link name="velodyne">
    <inertial>
      <mass value="0.01"/>
      <origin xyz="0 0 0"/>
      <inertia ixx="1e-7" ixy="0" ixz="0" iyy="1e-7" iyz="0" izz="1e-7"/>
    </inertial>
    <visual>
      <origin xyz="0 0 -0.0377"/>
      <geometry>
        <mesh filename="package://velodyne_description/meshes/VLP16_scan.dae"/>
      </geometry>
    </visual>
  </link>
  <!-- Gazebo requires the velodyne_gazebo_plugins package -->
  <gazebo reference="velodyne">
    <sensor name="velodyne-VLP16" type="ray">
      <pose>0 0 0 0 0 0</pose>
      <visualize>false</visualize>
      <update_rate>10</update_rate>
      <ray>
        <scan>
          <horizontal>
            <samples>901</samples>
            <resolution>0.2</resolution>
            <min_angle>-1.57</min_angle>
            <max_angle>1.57</max_angle>
          </horizontal>
          <vertical>
            <samples>32</samples>
            <resolution>1.33</resolution>
            <min_angle>-0.9599310885968828</min_angle>
            <max_angle> 0.261799387799</max_angle>
          </vertical>
        </scan>
        <range>
          <min>0.3</min>
          <max>10.0</max>
          <resolution>0.01</resolution>
        </range>
        <noise>
          <type>gaussian</type>
          <mean>0.0</mean>
          <stddev>0.0</stddev>
        </noise>
      </ray>
      <plugin filename="libgazebo_ros_velodyne_laser.so" name="gazebo_ros_laser_controller">
        <topicName>/velodyne_points</topicName>
        <frameName>velodyne</frameName>
        <min_range>0.3</min_range>
        <max_range>10.0</max_range>
        <gaussianNoise>0</gaussianNoise>
      </plugin>
    </sensor>
  </gazebo>
  <!--lidar_link-->
  <gazebo reference="lidar_link">
    <sensor name="rplidar" type="ray">
      <pose>0 0 0 0 0 0</pose>
      <visualize>false</visualize>
      <update_rate>5.5</update_rate>
      <ray>
        <scan>
          <horizontal>
            <samples>360</samples>
            <resolution>1</resolution>
            <min_angle>-3</min_angle>
            <max_angle>3</max_angle>
          </horizontal>
        </scan>
        <range>
          <min>0.10</min>
          <max>6.0</max>
          <resolution>0.01</resolution>
        </range>
        <noise>
          <type>gaussian</type>
          <mean>0.0</mean>
          <stddev>0.01</stddev>
        </noise>
      </ray>
      <plugin filename="libgazebo_ros_laser.so" name="gazebo_rplidar">
        <topicName>/scan</topicName>
        <frameName>lidar_link</frameName>
      </plugin>
    </sensor>
  </gazebo>
  <!-- Drive controller -->
  <gazebo>
    <plugin filename="libgazebo_ros_skid_steer_drive.so" name="skid_steer_drive_controller">
      <updateRate>100.0</updateRate>
      <robotNamespace/>
      <leftFrontJoint>left_front_wheel_link_joint</leftFrontJoint>
      <rightFrontJoint>right_front_wheel_link_joint</rightFrontJoint>
      <leftRearJoint>left_behind_wheel_link_joint</leftRearJoint>
      <rightRearJoint>right_behind_wheel_link_joint</rightRearJoint>
      <wheelSeparation>0.64</wheelSeparation>
      <wheelDiameter>0.33</wheelDiameter>
      <commandTopic>cmd_vel</commandTopic>
      <odometryTopic>odom</odometryTopic>
      <robotBaseFrame>base_footprint</robotBaseFrame>
      <odometryFrame>odom</odometryFrame>
      <torque>10000</torque>
      <topicName>cmd_vel</topicName>
      <broadcastTF>1</broadcastTF>
    </plugin>
  </gazebo>
  <!-- ros_control plugin -->
  <gazebo>
    <plugin filename="libgazebo_ros_control.so" name="gazebo_ros_control">
      <robotNamespace>/lzh_run_robot</robotNamespace>
      <legacyModeNS>true</legacyModeNS>
    </plugin>
  </gazebo>
  <!--friction-->
  <gazebo reference="left_front_wheel_link">
    <mu1>10000</mu1>
    <mu2>10000</mu2>
    <kp>10000000</kp>
    <kd>1</kd>
  </gazebo>
  <gazebo reference="left_behind_wheel_link">
    <mu1>10000</mu1>
    <mu2>10000</mu2>
    <kp>10000000</kp>
    <kd>1</kd>
  </gazebo>
  <gazebo reference="right_front_wheel_link">
    <mu1>10000</mu1>
    <mu2>10000</mu2>
    <kp>10000000</kp>
    <kd>1</kd>
  </gazebo>
  <gazebo reference="right_behind_wheel_link">
    <mu1>10000</mu1>
    <mu2>10000</mu2>
    <kp>10000000</kp>
    <kd>1</kd>
  </gazebo>
</robot>

